Workbook
Name Slicer_Diabetes_Status: #N/A
Name Slicer_Weight_issues: #N/A

Sheet Customer Names
A1: Customer ID | B1: name | C1: Title | D1: First Name | E1: Last name
A2: Id1 | B2: Hawks, Ms. Kelly | C2: {=INDEX(_xlfn.TEXTSPLIT(B2,{" , "," "}),2)} -> Ms. | D2: =_xlfn.TEXTAFTER(_xlfn.TEXTAFTER(B2,", ")," ") -> Kelly | E2: {=INDEX(_xlfn.TEXTSPLIT(B2,","),1)} -> Hawks
A3: Id2 | B3: Lehner, Mr. Matthew D | C3: {=INDEX(_xlfn.TEXTSPLIT(B3,{" , "," "}),2)} -> Mr. | D3: =_xlfn.TEXTAFTER(_xlfn.TEXTAFTER(B3,", ")," ") -> Matthew D | E3: {=INDEX(_xlfn.TEXTSPLIT(B3,","),1)} -> Lehner
A4: Id3 | B4: Lu, Mr. Phil | C4: {=INDEX(_xlfn.TEXTSPLIT(B4,{" , "," "}),2)} -> Mr. | D4: =_xlfn.TEXTAFTER(_xlfn.TEXTAFTER(B4,", ")," ") -> Phil | E4: {=INDEX(_xlfn.TEXTSPLIT(B4,","),1)} -> Lu
A5: Id4 | B5: Osborne, Ms. Kelsey | C5: {=INDEX(_xlfn.TEXTSPLIT(B5,{" , "," "}),2)} -> Ms. | D5: =_xlfn.TEXTAFTER(_xlfn.TEXTAFTER(B5,", ")," ") -> Kelsey | E5: {=INDEX(_xlfn.TEXTSPLIT(B5,","),1)} -> Osborne
A6: Id5 | B6: Kadala, Ms. Kristyn | C6: {=INDEX(_xlfn.TEXTSPLIT(B6,{" , "," "}),2)} -> Ms. | D6: =_xlfn.TEXTAFTER(_xlfn.TEXTAFTER(B6,", ")," ") -> Kristyn | E6: {=INDEX(_xlfn.TEXTSPLIT(B6,","),1)} -> Kadala
A7: Id6 | B7: Baker, Mr. Russell B. | C7: {=INDEX(_xlfn.TEXTSPLIT(B7,{" , "," "}),2)} -> Mr. | D7: =_xlfn.TEXTAFTER(_xlfn.TEXTAFTER(B7,", ")," ") -> Russell B. | E7: {=INDEX(_xlfn.TEXTSPLIT(B7,","),1)} -> Baker
A8: Id7 | B8: Macpherson, Mr. Scott | C8: {=INDEX(_xlfn.TEXTSPLIT(B8,{" , "," "}),2)} -> Mr. | D8: =_xlfn.TEXTAFTER(_xlfn.TEXTAFTER(B8,", ")," ") -> Scott | E8: {=INDEX(_xlfn.TEXTSPLIT(B8,","),1)} -> Macpherson
A9: Id8 | B9: Hallman, Mr. Stephen | C9: {=INDEX(_xlfn.TEXTSPLIT(B9,{" , "," "}),2)} -> Mr. | D9: =_xlfn.TEXTAFTER(_xlfn.TEXTAFTER(B9,", ")," ") -> Stephen | E9: {=INDEX(_xlfn.TEXTSPLIT(B9,","),1)} -> Hallman
A10: Id9 | B10: Moran, Mr. Patrick R. | C10: {=INDEX(_xlfn.TEXTSPLIT(B10,{" , "," "}),2)} -> Mr. | D10: =_xlfn.TEXTAFTER(_xlfn.TEXTAFTER(B10,", ")," ") -> Patrick R. | E10: {=INDEX(_xlfn.TEXTSPLIT(B10,","),1)} -> Moran
A11: Id10 | B11: Benner, Ms. Brooke N. | C11: {=INDEX(_xlfn.TEXTSPLIT(B11,{" , "," "}),2)} -> Ms. | D11: =_xlfn.TEXTAFTER(_xlfn.TEXTAFTER(B11,", ")," ") -> Brooke N. | E11: {=INDEX(_xlfn.TEXTSPLIT(B11,","),1)} -> Benner
A12: Id11 | B12: Fierro Vargas, Ms. Paola Andrea | C12: {=INDEX(_xlfn.TEXTSPLIT(B12,{" , "," "}),3)} -> Ms. | D12: =_xlfn.TEXTAFTER(_xlfn.TEXTAFTER(B12,", ")," ") -> Paola Andrea | E12: {=INDEX(_xlfn.TEXTSPLIT(B12,","),1)} -> Fierro Vargas
A13: Id12 | B13: Franz, Mr. David | C13: {=INDEX(_xlfn.TEXTSPLIT(B13,{" , "," "}),2)} -> Mr. | D13: =_xlfn.TEXTAFTER(_xlfn.TEXTAFTER(B13,", ")," ") -> David | E13: {=INDEX(_xlfn.TEXTSPLIT(B13,","),1)} -> Franz
A14: Id13 | B14: Foster, Mr. Wade | C14: {=INDEX(_xlfn.TEXTSPLIT(B14,{" , "," "}),2)} -> Mr. | D14: =_xlfn.TEXTAFTER(_xlfn.TEXTAFTER(B14,", ")," ") -> Wade | E14: {=INDEX(_xlfn.TEXTSPLIT(B14,","),1)} -> Foster
A15: Id14 | B15: Tenorio, Mr. Franklin | C15: {=INDEX(_xlfn.TEXTSPLIT(B15,{" , "," "}),2)} -> Mr. | D15: =_xlfn.TEXTAFTER(_xlfn.TEXTAFTER(B15,", ")," ") -> Franklin | E15: {=INDEX(_xlfn.TEXTSPLIT(B15,","),1)} -> Tenorio
A16: Id15 | B16: Rios, Ms. Leilani M. | C16: {=INDEX(_xlfn.TEXTSPLIT(B16,{" , "," "}),2)} -> Ms. | D16: =_xlfn.TEXTAFTER(_xlfn.TEXTAFTER(B16,", ")," ") -> Leilani M. | E16: {=INDEX(_xlfn.TEXTSPLIT(B16,","),1)} -> Rios
A17: Id16 | B17: Viau-Dupuis, Mr. Philippe | C17: {=INDEX(_xlfn.TEXTSPLIT(B17,{" , "," "}),2)} -> Mr. | D17: =_xlfn.TEXTAFTER(_xlfn.TEXTAFTER(B17,", ")," ") -> Philippe | E17: {=INDEX(_xlfn.TEXTSPLIT(B17,","),1)} -> Viau-Dupuis
A18: Id17 | B18: Cronin, Ms. Jennifer A. | C18: {=INDEX(_xlfn.TEXTSPLIT(B18,{" , "," "}),2)} -> Ms. | D18: =_xlfn.TEXTAFTER(_xlfn.TEXTAFTER(B18,", ")," ") -> Jennifer A. | E18: {=INDEX(_xlfn.TEXTSPLIT(B18,","),1)} -> Cronin
A19: Id18 | B19: Noordstar, Ms. Christina M. | C19: {=INDEX(_xlfn.TEXTSPLIT(B19,{" , "," "}),2)} -> Ms. | D19: =_xlfn.TEXTAFTER(_xlfn.TEXTAFTER(B19,", ")," ") -> Christina M. | E19: {=INDEX(_xlfn.TEXTSPLIT(B19,","),1)} -> Noordstar
A20: Id19 | B20: Boudalia, Mr. Said Sr. | C20: {=INDEX(_xlfn.TEXTSPLIT(B20,{" , "," "}),2)} -> Mr. | D20: =_xlfn.TEXTAFTER(_xlfn.TEXTAFTER(B20,", ")," ") -> Said Sr. | E20: {=INDEX(_xlfn.TEXTSPLIT(B20,","),1)} -> Boudalia
A21: Id20 | B21: Flor, Mr. John | C21: {=INDEX(_xlfn.TEXTSPLIT(B21,{" , "," "}),2)} -> Mr. | D21: =_xlfn.TEXTAFTER(_xlfn.TEXTAFTER(B21,", ")," ") -> John | E21: {=INDEX(_xlfn.TEXTSPLIT(B21,","),1)} -> Flor
A22: Id21 | B22: Fennon, Mr. Myles | C22: {=INDEX(_xlfn.TEXTSPLIT(B22,{" , "," "}),2)} -> Mr. | D22: =_xlfn.TEXTAFTER(_xlfn.TEXTAFTER(B22,", ")," ") -> Myles | E22: {=INDEX(_xlfn.TEXTSPLIT(B22,","),1)} -> Fennon
A23: Id22 | B23: Hribar, Ms. Madelyn C | C23: {=INDEX(_xlfn.TEXTSPLIT(B23,{" , "," "}),2)} -> Ms. | D23: =_xlfn.TEXTAFTER(_xlfn.TEXTAFTER(B23,", ")," ") -> Madelyn C | E23: {=INDEX(_xlfn.TEXTSPLIT(B23,","),1)} -> Hribar
A24: Id23 | B24: Tassello, Ms. Nicole | C24: {=INDEX(_xlfn.TEXTSPLIT(B24,{" , "," "}),2)} -> Ms. | D24: =_xlfn.TEXTAFTER(_xlfn.TEXTAFTER(B24,", ")," ") -> Nicole | E24: {=INDEX(_xlfn.TEXTSPLIT(B24,","),1)} -> Tassello
... A49: Id48 | B49: Peters, Ms. Melissa L | C49: {=INDEX(_xlfn.TEXTSPLIT(B49,{" , "," "}),2)} -> Ms. | D49: =_xlfn.TEXTAFTER(_xlfn.TEXTAFTER(B49,", ")," ") -> Melissa L | E49: {=INDEX(_xlfn.TEXTSPLIT(B49,","),1)} -> Peters
A50: Id49 | B50: De Simone, Mr. Flavio | C50: {=INDEX(_xlfn.TEXTSPLIT(B50,{" , "," "}),3)} -> Mr. | D50: =_xlfn.TEXTAFTER(_xlfn.TEXTAFTER(B50,", ")," ") -> Flavio | E50: {=INDEX(_xlfn.TEXTSPLIT(B50,","),1)} -> De Simone
A51: Id50 | B51: Beckett, Mr. Ryan | C51: {=INDEX(_xlfn.TEXTSPLIT(B51,{" , "," "}),2)} -> Mr. | D51: =_xlfn.TEXTAFTER(_xlfn.TEXTAFTER(B51,", ")," ") -> Ryan | E51: {=INDEX(_xlfn.TEXTSPLIT(B51,","),1)} -> Beckett
A52: Id51 | B52: Sobrilsky, Mr. Anthony J. | C52: {=INDEX(_xlfn.TEXTSPLIT(B52,{" , "," "}),2)} -> Mr. | D52: =_xlfn.TEXTAFTER(_xlfn.TEXTAFTER(B52,", ")," ") -> Anthony J. | E52: {=INDEX(_xlfn.TEXTSPLIT(B52,","),1)} -> Sobrilsky
A53: Id52 | B53: Wang, Ms. Alex | C53: {=INDEX(_xlfn.TEXTSPLIT(B53,{" , "," "}),2)} -> Ms. | D53: =_xlfn.TEXTAFTER(_xlfn.TEXTAFTER(B53,", ")," ") -> Alex | E53: {=INDEX(_xlfn.TEXTSPLIT(B53,","),1)} -> Wang
A54: Id53 | B54: Campa, Mr. David | C54: {=INDEX(_xlfn.TEXTSPLIT(B54,{" , "," "}),2)} -> Mr. | D54: =_xlfn.TEXTAFTER(_xlfn.TEXTAFTER(B54,", ")," ") -> David | E54: {=INDEX(_xlfn.TEXTSPLIT(B54,","),1)} -> Campa
A55: Id54 | B55: Clifford, Mr. Andrew B | C55: {=INDEX(_xlfn.TEXTSPLIT(B55,{" , "," "}),2)} -> Mr. | D55: =_xlfn.TEXTAFTER(_xlfn.TEXTAFTER(B55,", ")," ") -> Andrew B | E55: {=INDEX(_xlfn.TEXTSPLIT(B55,","),1)} -> Clifford
A56: Id55 | B56: Dalmata, Ms. Dara E | C56: {=INDEX(_xlfn.TEXTSPLIT(B56,{" , "," "}),2)} -> Ms. | D56: =_xlfn.TEXTAFTER(_xlfn.TEXTAFTER(B56,", ")," ") -> Dara E | E56: {=INDEX(_xlfn.TEXTSPLIT(B56,","),1)} -> Dalmata
A57: Id56 | B57: Vishik, Ms. Inna | C57: {=INDEX(_xlfn.TEXTSPLIT(B57,{" , "," "}),2)} -> Ms. | D57: =_xlfn.TEXTAFTER(_xlfn.TEXTAFTER(B57,", ")," ") -> Inna | E57: {=INDEX(_xlfn.TEXTSPLIT(B57,","),1)} -> Vishik
A58: Id57 | B58: Schorr, Mr. Ari | C58: {=INDEX(_xlfn.TEXTSPLIT(B58,{" , "," "}),2)} -> Mr. | D58: =_xlfn.TEXTAFTER(_xlfn.TEXTAFTER(B58,", ")," ") -> Ari | E58: {=INDEX(_xlfn.TEXTSPLIT(B58,","),1)} -> Schorr
A59: Id58 | B59: Lusardi, Ms. Lindsey | C59: {=INDEX(_xlfn.TEXTSPLIT(B59,{" , "," "}),2)} -> Ms. | D59: =_xlfn.TEXTAFTER(_xlfn.TEXTAFTER(B59,", ")," ") -> Lindsey | E59: {=INDEX(_xlfn.TEXTSPLIT(B59,","),1)} -> Lusardi
A60: Id59 | B60: Rayner, Mr. Kenny | C60: {=INDEX(_xlfn.TEXTSPLIT(B60,{" , "," "}),2)} -> Mr. | D60: =_xlfn.TEXTAFTER(_xlfn.TEXTAFTER(B60,", ")," ") -> Kenny | E60: {=INDEX(_xlfn.TEXTSPLIT(B60,","),1)} -> Rayner
A61: Id60 | B61: Voghel, Ms. Louise | C61: {=INDEX(_xlfn.TEXTSPLIT(B61,{" , "," "}),2)} -> Ms. | D61: =_xlfn.TEXTAFTER(_xlfn.TEXTAFTER(B61,", ")," ") -> Louise | E61: {=INDEX(_xlfn.TEXTSPLIT(B61,","),1)} -> Voghel
A62: Id61 | B62: Rieth, Mr. Cameron | C62: {=INDEX(_xlfn.TEXTSPLIT(B62,{" , "," "}),2)} -> Mr. | D62: =_xlfn.TEXTAFTER(_xlfn.TEXTAFTER(B62,", ")," ") -> Cameron | E62: {=INDEX(_xlfn.TEXTSPLIT(B62,","),1)} -> Rieth
... A97: Id96 | B97: Boland, Mr. Thomas | C97: {=INDEX(_xlfn.TEXTSPLIT(B97,{" , "," "}),2)} -> Mr. | D97: =_xlfn.TEXTAFTER(_xlfn.TEXTAFTER(B97,", ")," ") -> Thomas | E97: {=INDEX(_xlfn.TEXTSPLIT(B97,","),1)} -> Boland
A98: Id97 | B98: Van Hout, Ms. Pamela J. | C98: {=INDEX(_xlfn.TEXTSPLIT(B98,{" , "," "}),3)} -> Ms. | D98: =_xlfn.TEXTAFTER(_xlfn.TEXTAFTER(B98,", ")," ") -> Pamela J. | E98: {=INDEX(_xlfn.TEXTSPLIT(B98,","),1)} -> Van Hout
...

Sheet Medical Examinations
A1: Customer ID | B1: BMI | C1: HBA1C | D1: Heart Issues | E1: Any Transplants | F1: Cancer history | G1: NumberOfMajorSurgeries | H1: smoker | I1: BMI | J1: DIABETES STATUS | L1: Column1 | M1: Column2
A2: Id1 | B2: 47.41 | C2: 7.47 | D2: NO | E2: No | F2: No | G2: 0 | H2: YES | I2: =IF(B2<18.5,"underweight",IF(B2<25,"normal weight",IF(B2<30,"overweight","obesity"))) -> obesity | J2: =IF(C2<5.7,"normal",IF(C2<6.5,"prediabetes","diabetes")) -> diabetes | L2: checking missing values"?"=
A3: Id2 | B3: 30.36 | C3: 5.77 | D3: NO | E3: No | F3: No | G3: 0 | H3: YES | I3: =IF(B3<18.5,"underweight",IF(B3<25,"normal weight",IF(B3<30,"overweight","obesity"))) -> obesity | J3: =IF(C3<5.7,"normal",IF(C3<6.5,"prediabetes","diabetes")) -> prediabetes | L3: Customer ID | M3: =COUNTIF(A:A,"?") -> 0
A4: Id3 | B4: 34.485 | C4: 11.87 | D4: YES | E4: No | F4: No | G4: 2 | H4: YES | I4: =IF(B4<18.5,"underweight",IF(B4<25,"normal weight",IF(B4<30,"overweight","obesity"))) -> obesity | J4: =IF(C4<5.7,"normal",IF(C4<6.5,"prediabetes","diabetes")) -> diabetes | L4: BMI | M4: =COUNTIF(B:B,"?") -> 0
A5: Id4 | B5: 38.095 | C5: 6.05 | D5: NO | E5: No | F5: No | G5: 0 | H5: YES | I5: =IF(B5<18.5,"underweight",IF(B5<25,"normal weight",IF(B5<30,"overweight","obesity"))) -> obesity | J5: =IF(C5<5.7,"normal",IF(C5<6.5,"prediabetes","diabetes")) -> prediabetes | L5: HBA1C | M5: =COUNTIF(C:C,"?") -> 0
A6: Id5 | B6: 35.53 | C6: 5.45 | D6: NO | E6: No | F6: No | G6: 0 | H6: YES | I6: =IF(B6<18.5,"underweight",IF(B6<25,"normal weight",IF(B6<30,"overweight","obesity"))) -> obesity | J6: =IF(C6<5.7,"normal",IF(C6<6.5,"prediabetes","diabetes")) -> normal | L6: Heart issues | M6: =COUNTIF(D:D,"?") -> 0
A7: Id6 | B7: 32.8 | C7: 6.59 | D7: NO | E7: No | F7: No | G7: 0 | H7: YES | I7: =IF(B7<18.5,"underweight",IF(B7<25,"normal weight",IF(B7<30,"overweight","obesity"))) -> obesity | J7: =IF(C7<5.7,"normal",IF(C7<6.5,"prediabetes","diabetes")) -> diabetes | L7: Any Transplants | M7: =COUNTIF(E:E,"?") -> 0
A8: Id7 | B8: 36.4 | C8: 6.07 | D8: NO | E8: No | F8: No | G8: 0 | H8: YES | I8: =IF(B8<18.5,"underweight",IF(B8<25,"normal weight",IF(B8<30,"overweight","obesity"))) -> obesity | J8: =IF(C8<5.7,"normal",IF(C8<6.5,"prediabetes","diabetes")) -> prediabetes | L8: Cancer History | M8: =COUNTIF(F:F,"?") -> 0
A9: Id8 | B9: 36.96 | C9: 7.93 | D9: NO | E9: No | F9: No | G9: 3 | H9: YES | I9: =IF(B9<18.5,"underweight",IF(B9<25,"normal weight",IF(B9<30,"overweight","obesity"))) -> obesity | J9: =IF(C9<5.7,"normal",IF(C9<6.5,"prediabetes","diabetes")) -> diabetes | L9: Number of major Surgeries | M9: =COUNTIF(G:G,"?") -> 0
A10: Id9 | B10: 41.14 | C10: 9.58 | D10: YES | E10: No | F10: Yes | G10: 1 | H10: YES | I10: =IF(B10<18.5,"underweight",IF(B10<25,"normal weight",IF(B10<30,"overweight","obesity"))) -> obesity | J10: =IF(C10<5.7,"normal",IF(C10<6.5,"prediabetes","diabetes")) -> diabetes | L10: Smoker | M10: =COUNTIF(G:G,"?") -> 0
A11: Id10 | B11: 38.06 | C11: 10.79 | D11: NO | E11: No | F11: No | G11: 0 | H11: YES | I11: =IF(B11<18.5,"underweight",IF(B11<25,"normal weight",IF(B11<30,"overweight","obesity"))) -> obesity | J11: =IF(C11<5.7,"normal",IF(C11<6.5,"prediabetes","diabetes")) -> diabetes
A12: Id11 | B12: 37.7 | C12: 5.96 | D12: YES | E12: No | F12: No | G12: 2 | H12: YES | I12: =IF(B12<18.5,"underweight",IF(B12<25,"normal weight",IF(B12<30,"overweight","obesity"))) -> obesity | J12: =IF(C12<5.7,"normal",IF(C12<6.5,"prediabetes","diabetes")) -> prediabetes
A13: Id12 | B13: 42.13 | C13: 11.9 | D13: NO | E13: No | F13: No | G13: 0 | H13: YES | I13: =IF(B13<18.5,"underweight",IF(B13<25,"normal weight",IF(B13<30,"overweight","obesity"))) -> obesity | J13: =IF(C13<5.7,"normal",IF(C13<6.5,"prediabetes","diabetes")) -> diabetes
A14: Id13 | B14: 40.92 | C14: 8.41 | D14: NO | E14: No | F14: No | G14: 0 | H14: YES | I14: =IF(B14<18.5,"underweight",IF(B14<25,"normal weight",IF(B14<30,"overweight","obesity"))) -> obesity | J14: =IF(C14<5.7,"normal",IF(C14<6.5,"prediabetes","diabetes")) -> diabetes
A15: Id14 | B15: 40.565 | C15: 7.02 | D15: NO | E15: No | F15: No | G15: 0 | H15: YES | I15: =IF(B15<18.5,"underweight",IF(B15<25,"normal weight",IF(B15<30,"overweight","obesity"))) -> obesity | J15: =IF(C15<5.7,"normal",IF(C15<6.5,"prediabetes","diabetes")) -> diabetes
A16: Id15 | B16: 36.385 | C16: 7.59 | D16: YES | E16: No | F16: No | G16: 2 | H16: YES | I16: =IF(B16<18.5,"underweight",IF(B16<25,"normal weight",IF(B16<30,"overweight","obesity"))) -> obesity | J16: =IF(C16<5.7,"normal",IF(C16<6.5,"prediabetes","diabetes")) -> diabetes
A17: Id16 | B17: 39.9 | C17: 11.32 | D17: NO | E17: No | F17: No | G17: 0 | H17: YES | I17: =IF(B17<18.5,"underweight",IF(B17<25,"normal weight",IF(B17<30,"overweight","obesity"))) -> obesity | J17: =IF(C17<5.7,"normal",IF(C17<6.5,"prediabetes","diabetes")) -> diabetes
A18: Id17 | B18: 33.8 | C18: 7.67 | D18: NO | E18: No | F18: No | G18: 3 | H18: YES | I18: =IF(B18<18.5,"underweight",IF(B18<25,"normal weight",IF(B18<30,"overweight","obesity"))) -> obesity | J18: =IF(C18<5.7,"normal",IF(C18<6.5,"prediabetes","diabetes")) -> diabetes
A19: Id18 | B19: 36.765 | C19: 7.29 | D19: YES | E19: No | F19: Yes | G19: 1 | H19: YES | I19: =IF(B19<18.5,"underweight",IF(B19<25,"normal weight",IF(B19<30,"overweight","obesity"))) -> obesity | J19: =IF(C19<5.7,"normal",IF(C19<6.5,"prediabetes","diabetes")) -> diabetes
A20: Id19 | B20: 36.955 | C20: 4.72 | D20: YES | E20: No | F20: No | G20: 1 | H20: YES | I20: =IF(B20<18.5,"underweight",IF(B20<25,"normal weight",IF(B20<30,"overweight","obesity"))) -> obesity | J20: =IF(C20<5.7,"normal",IF(C20<6.5,"prediabetes","diabetes")) -> normal
A21: Id20 | B21: 42.9 | C21: 11.41 | D21: NO | E21: No | F21: No | G21: 0 | H21: YES | I21: =IF(B21<18.5,"underweight",IF(B21<25,"normal weight",IF(B21<30,"overweight","obesity"))) -> obesity | J21: =IF(C21<5.7,"normal",IF(C21<6.5,"prediabetes","diabetes")) -> diabetes
A22: Id21 | B22: 36.3 | C22: 11.5 | D22: YES | E22: No | F22: No | G22: 2 | H22: YES | I22: =IF(B22<18.5,"underweight",IF(B22<25,"normal weight",IF(B22<30,"overweight","obesity"))) -> obesity | J22: =IF(C22<5.7,"normal",IF(C22<6.5,"prediabetes","diabetes")) -> diabetes
... A2336: Id2335 | B2336: 17.58 | C2336: 4.51 | D2336: NO | E2336: No | F2336: No | G2336: 1 | H2336: YES | I2336: =IF(B2336<18.5,"underweight",IF(B2336<25,"normal weight",IF(B2336<30,"overweight","obesity"))) -> underweight | J2336: =IF(C2336<5.7,"normal",IF(C2336<6.5,"prediabetes","diabetes")) -> normal

Sheet Hospitalisation Details
A1: Customer ID | B1: year | C1: month | D1: date | E1: children | F1: charges | G1: Hospital tier | H1: City tier | I1: State ID | J1: Date of birth | K1: age | N1: checking missing values"?"= | O1: Column1
A2: Id2335 | B2: 1992 | C2: Jul | D2: 9 | E2: 0 | F2: 563.84 | G2: tier - 2 | H2: tier - 3 | I2: R1013 | J2: =_xlfn.CONCAT(D2,"-",C2,"-",B2) -> 9-Jul-1992 | K2: =YEAR(DATE(2023,6,8))-YEAR(J2) -> 31 | N2: Customer ID | O2: =COUNTIF(A:A,"?") -> 6
A3: Id2334 | B3: 1992 | C3: Nov | D3: 30 | E3: 0 | F3: 570.62 | G3: tier - 2 | H3: tier - 1 | I3: R1013 | J3: =_xlfn.CONCAT(D3,"-",C3,"-",B3) -> 30-Nov-1992 | K3: =YEAR(DATE(2023,6,8))-YEAR(J3) -> 31 | N3: Year | O3: =COUNTIF(B:B,"?") -> 0
A4: Id2333 | B4: 1993 | C4: Jun | D4: 30 | E4: 0 | F4: 600 | G4: tier - 2 | H4: tier - 1 | I4: R1013 | J4: =_xlfn.CONCAT(D4,"-",C4,"-",B4) -> 30-Jun-1993 | K4: =YEAR(DATE(2023,6,8))-YEAR(J4) -> 30 | N4: Month | O4: =COUNTIF(C:C,"?") -> 0
A5: Id2332 | B5: 1992 | C5: Sep | D5: 13 | E5: 0 | F5: 604.54 | G5: tier - 3 | H5: tier - 3 | I5: R1013 | J5: =_xlfn.CONCAT(D5,"-",C5,"-",B5) -> 13-Sep-1992 | K5: =YEAR(DATE(2023,6,8))-YEAR(J5) -> 31 | N5: Date | O5: =COUNTIF(D:D,"?") -> 0
A6: Id2331 | B6: 1998 | C6: Jul | D6: 27 | E6: 0 | F6: 637.26 | G6: tier - 3 | H6: tier - 3 | I6: R1013 | J6: =_xlfn.CONCAT(D6,"-",C6,"-",B6) -> 27-Jul-1998 | K6: =YEAR(DATE(2023,6,8))-YEAR(J6) -> 25 | N6: Children | O6: =COUNTIF(E:E,"?") -> 0
A7: Id2330 | B7: 2001 | C7: Nov | D7: 20 | E7: 0 | F7: 646.14 | G7: tier - 3 | H7: tier - 3 | I7: R1012 | J7: =_xlfn.CONCAT(D7,"-",C7,"-",B7) -> 20-Nov-2001 | K7: =YEAR(DATE(2023,6,8))-YEAR(J7) -> 22 | N7: charges | O7: =COUNTIF(F:F,"?") -> 0
A8: Id2329 | B8: 1993 | C8: Jun | D8: 1 | E8: 0 | F8: 650 | G8: tier - 3 | H8: tier - 3 | I8: R1013 | J8: =_xlfn.CONCAT(D8,"-",C8,"-",B8) -> 1-Jun-1993 | K8: =YEAR(DATE(2023,6,8))-YEAR(J8) -> 30 | N8: Hospital Tier | O8: =COUNTIF(G:G,"?") -> 0
A9: Id2328 | B9: 1995 | C9: Jul | D9: 4 | E9: 0 | F9: 650 | G9: tier - 3 | H9: tier - 3 | I9: R1013 | J9: =_xlfn.CONCAT(D9,"-",C9,"-",B9) -> 4-Jul-1995 | K9: =YEAR(DATE(2023,6,8))-YEAR(J9) -> 28 | N9: City Tier | O9: =COUNTIF(H:H,"?") -> 0
A10: Id2327 | B10: 2002 | C10: Nov | D10: 29 | E10: 0 | F10: 668 | G10: tier - 3 | H10: tier - 2 | I10: R1012 | J10: =_xlfn.CONCAT(D10,"-",C10,"-",B10) -> 29-Nov-2002 | K10: =YEAR(DATE(2023,6,8))-YEAR(J10) -> 21 | N10: State ID | O10: =COUNTIF(I:I,"?") -> 0
A11: Id2326 | B11: 1997 | C11: Nov | D11: 9 | E11: 0 | F11: 670 | G11: tier - 3 | H11: tier - 3 | I11: R1013 | J11: =_xlfn.CONCAT(D11,"-",C11,"-",B11) -> 9-Nov-1997 | K11: =YEAR(DATE(2023,6,8))-YEAR(J11) -> 26
A12: Id2325 | B12: 2001 | C12: Sep | D12: 12 | E12: 0 | F12: 687.54 | G12: tier - 3 | H12: tier - 2 | I12: R1013 | J12: =_xlfn.CONCAT(D12,"-",C12,"-",B12) -> 12-Sep-2001 | K12: =YEAR(DATE(2023,6,8))-YEAR(J12) -> 22
A13: Id2324 | B13: 1999 | C13: Dec | D13: 26 | E13: 0 | F13: 700 | G13: tier -3 | H13: tier - 3 | I13: R1013 | J13: =_xlfn.CONCAT(D13,"-",C13,"-",B13) -> 26-Dec-1999 | K13: =YEAR(DATE(2023,6,8))-YEAR(J13) -> 24 | N13: Average Number from Year | O13: =AVERAGE(B:B) -> 1982.8408
A14: Id2323 | B14: 1999 | C14: Dec | D14: 14 | E14: 0 | F14: 722.99 | G14: tier - 3 | H14: tier - 1 | I14: R1013 | J14: =_xlfn.CONCAT(D14,"-",C14,"-",B14) -> 14-Dec-1999 | K14: =YEAR(DATE(2023,6,8))-YEAR(J14) -> 24
A15: Id2322 | B15: 2002 | C15: Sep | D15: 19 | E15: 0 | F15: 750 | G15: tier - 3 | H15: tier - 1 | I15: R1012 | J15: =_xlfn.CONCAT(D15,"-",C15,"-",B15) -> 19-Sep-2002 | K15: =YEAR(DATE(2023,6,8))-YEAR(J15) -> 21
A16: Id2321 | B16: 1993 | C16: Aug | D16: 9 | E16: 0 | F16: 760 | G16: tier - 3 | H16: tier - 1 | I16: R1013 | J16: =_xlfn.CONCAT(D16,"-",C16,"-",B16) -> 9-Aug-1993 | K16: =YEAR(DATE(2023,6,8))-YEAR(J16) -> 30
A17: Id2320 | B17: 1996 | C17: Oct | D17: 22 | E17: 0 | F17: 760 | G17: tier - 3 | H17: tier - 3 | I17: R1013 | J17: =_xlfn.CONCAT(D17,"-",C17,"-",B17) -> 22-Oct-1996 | K17: =YEAR(DATE(2023,6,8))-YEAR(J17) -> 27
A18: Id2319 | B18: 1993 | C18: Jun | D18: 28 | E18: 0 | F18: 770 | G18: tier - 3 | H18: tier - 3 | I18: R1013 | J18: =_xlfn.CONCAT(D18,"-",C18,"-",B18) -> 28-Jun-1993 | K18: =YEAR(DATE(2023,6,8))-YEAR(J18) -> 30
A19: Id2318 | B19: 1996 | C19: Sep | D19: 18 | E19: 0 | F19: 770.38 | G19: tier - 3 | H19: tier - 2 | I19: R1012 | J19: =_xlfn.CONCAT(D19,"-",C19,"-",B19) -> 18-Sep-1996 | K19: =YEAR(DATE(2023,6,8))-YEAR(J19) -> 27
A20: Id2317 | B20: 1995 | C20: Dec | D20: 7 | E20: 0 | F20: 773.54 | G20: tier - 3 | H20: tier - 2 | I20: R1013 | J20: =_xlfn.CONCAT(D20,"-",C20,"-",B20) -> 7-Dec-1995 | K20: =YEAR(DATE(2023,6,8))-YEAR(J20) -> 28
A21: Id2316 | B21: 2004 | C21: Oct | D21: 7 | E21: 0 | F21: 830.52 | G21: tier - 3 | H21: tier - 2 | I21: R1011 | J21: =_xlfn.CONCAT(D21,"-",C21,"-",B21) -> 7-Oct-2004 | K21: =YEAR(DATE(2023,6,8))-YEAR(J21) -> 19
A22: Id2315 | B22: 2000 | C22: Nov | D22: 18 | E22: 0 | F22: 865.41 | G22: tier - 3 | H22: tier - 1 | I22: R1013 | J22: =_xlfn.CONCAT(D22,"-",C22,"-",B22) -> 18-Nov-2000 | K22: =YEAR(DATE(2023,6,8))-YEAR(J22) -> 23
A23: Id2314 | B23: 1993 | C23: Nov | D23: 27 | E23: 0 | F23: 896.21 | G23: tier - 3 | H23: tier - 1 | I23: R1013 | J23: =_xlfn.CONCAT(D23,"-",C23,"-",B23) -> 27-Nov-1993 | K23: =YEAR(DATE(2023,6,8))-YEAR(J23) -> 30
A24: Id2313 | B24: 1994 | C24: Oct | D24: 30 | E24: 0 | F24: 915.07 | G24: tier - 3 | H24: tier - 1 | I24: R1013 | J24: =_xlfn.CONCAT(D24,"-",C24,"-",B24) -> 30-Oct-1994 | K24: =YEAR(DATE(2023,6,8))-YEAR(J24) -> 29
A25: Id2312 | B25: 1995 | C25: Oct | D25: 28 | E25: 0 | F25: 928.59 | G25: tier - 3 | H25: tier - 1 | I25: R1013 | J25: =_xlfn.CONCAT(D25,"-",C25,"-",B25) -> 28-Oct-1995 | K25: =YEAR(DATE(2023,6,8))-YEAR(J25) -> 28
... A2344: Id1 | B2344: 1968 | C2344: Oct | D2344: 12 | E2344: 0 | F2344: 63770.43 | G2344: tier - 1 | H2344: tier - 3 | I2344: R1013 | J2344: =_xlfn.CONCAT(D2344,"-",C2344,"-",B2344) -> 12-Oct-1968 | K2344: =YEAR(DATE(2023,6,8))-YEAR(J2344) -> 55

Sheet Healthcare
A1: Customer ID | B1: Customer name | C1: BMI | D1: HBA1C | E1: Heart Issues | F1: Any Transplants | G1: Cancer history | H1: Number of major surgeries | I1: Smoker | J1: Weight Status | K1: Diabetes Status | L1: DOB | M1: Charges | N1: Hospital Tier | O1: city Tier | P1: state ID | Q1: Age
A2: =VLOOKUP('Medical Examinations'!A2,'Medical Examinations'!A:A,1,FALSE) -> Id1 | B2: =VLOOKUP(A2,'Customer Names'!A:E,4,FALSE) -> Kelly | C2: =VLOOKUP(A2,'Medical Examinations'!A:J,2,FALSE) -> 47.41 | D2: =VLOOKUP(A2,'Medical Examinations'!A:J,3,FALSE) -> 7.47 | E2: =VLOOKUP(A2,'Medical Examinations'!A:J,4,FALSE) -> NO | F2: =VLOOKUP(A2,'Medical Examinations'!A:J,5,FALSE) -> No | G2: =VLOOKUP(A2,'Medical Examinations'!A:J,6,FALSE) -> No | H2: =VLOOKUP(A2,'Medical Examinations'!A:J,7,FALSE) -> 0 | I2: =VLOOKUP(A2,'Medical Examinations'!A:J,8,FALSE) -> YES | J2: =VLOOKUP(A2,'Medical Examinations'!A:J,9,FALSE) -> obesity | K2: =VLOOKUP(A2,'Medical Examinations'!A:J,10,FALSE) -> diabetes | L2: =VLOOKUP(Healthcare!A2,'Hospitalisation Details'!A:K,10,FALSE) -> 12-Oct-1968 | M2: =VLOOKUP(A2,'Hospitalisation Details'!A:K,6,FALSE) -> 63770.43 | N2: =VLOOKUP(A2,'Hospitalisation Details'!A:K,7,FALSE) -> tier - 1 | O2: =VLOOKUP(A2,'Hospitalisation Details'!A:K,8,FALSE) -> tier - 3 | P2: =VLOOKUP(A2,'Hospitalisation Details'!A:K,9,FALSE) -> R1013 | Q2: =VLOOKUP(A2,'Hospitalisation Details'!A:K,11,FALSE) -> 55
A3: =VLOOKUP('Medical Examinations'!A3,'Medical Examinations'!A:A,1,FALSE) -> Id2 | B3: =VLOOKUP(A3,'Customer Names'!A:E,4,FALSE) -> Matthew D | C3: =VLOOKUP(A3,'Medical Examinations'!A:J,2,FALSE) -> 30.36 | D3: =VLOOKUP(A3,'Medical Examinations'!A:J,3,FALSE) -> 5.77 | E3: =VLOOKUP(A3,'Medical Examinations'!A:J,4,FALSE) -> NO | F3: =VLOOKUP(A3,'Medical Examinations'!A:J,5,FALSE) -> No | G3: =VLOOKUP(A3,'Medical Examinations'!A:J,6,FALSE) -> No | H3: =VLOOKUP(A3,'Medical Examinations'!A:J,7,FALSE) -> 0 | I3: =VLOOKUP(A3,'Medical Examinations'!A:J,8,FALSE) -> YES | J3: =VLOOKUP(A3,'Medical Examinations'!A:J,9,FALSE) -> obesity | K3: =VLOOKUP(A3,'Medical Examinations'!A:J,10,FALSE) -> prediabetes | L3: =VLOOKUP(Healthcare!A3,'Hospitalisation Details'!A:K,10,FALSE) -> 8-Jun-1977 | M3: =VLOOKUP(A3,'Hospitalisation Details'!A:K,6,FALSE) -> 62592.87 | N3: =VLOOKUP(A3,'Hospitalisation Details'!A:K,7,FALSE) -> tier - 2 | O3: =VLOOKUP(A3,'Hospitalisation Details'!A:K,8,FALSE) -> tier - 3 | P3: =VLOOKUP(A3,'Hospitalisation Details'!A:K,9,FALSE) -> R1013 | Q3: =VLOOKUP(A3,'Hospitalisation Details'!A:K,11,FALSE) -> 46
A4: =VLOOKUP('Medical Examinations'!A4,'Medical Examinations'!A:A,1,FALSE) -> Id3 | B4: =VLOOKUP(A4,'Customer Names'!A:E,4,FALSE) -> Phil | C4: =VLOOKUP(A4,'Medical Examinations'!A:J,2,FALSE) -> 34.485 | D4: =VLOOKUP(A4,'Medical Examinations'!A:J,3,FALSE) -> 11.87 | E4: =VLOOKUP(A4,'Medical Examinations'!A:J,4,FALSE) -> YES | F4: =VLOOKUP(A4,'Medical Examinations'!A:J,5,FALSE) -> No | G4: =VLOOKUP(A4,'Medical Examinations'!A:J,6,FALSE) -> No | H4: =VLOOKUP(A4,'Medical Examinations'!A:J,7,FALSE) -> 2 | I4: =VLOOKUP(A4,'Medical Examinations'!A:J,8,FALSE) -> YES | J4: =VLOOKUP(A4,'Medical Examinations'!A:J,9,FALSE) -> obesity | K4: =VLOOKUP(A4,'Medical Examinations'!A:J,10,FALSE) -> diabetes | L4: =VLOOKUP(Healthcare!A4,'Hospitalisation Details'!A:K,10,FALSE) -> 11-Sep-1970 | M4: =VLOOKUP(A4,'Hospitalisation Details'!A:K,6,FALSE) -> 60021.4 | N4: =VLOOKUP(A4,'Hospitalisation Details'!A:K,7,FALSE) -> tier - 1 | O4: =VLOOKUP(A4,'Hospitalisation Details'!A:K,8,FALSE) -> tier - 1 | P4: =VLOOKUP(A4,'Hospitalisation Details'!A:K,9,FALSE) -> R1012 | Q4: =VLOOKUP(A4,'Hospitalisation Details'!A:K,11,FALSE) -> 53
A5: =VLOOKUP('Medical Examinations'!A5,'Medical Examinations'!A:A,1,FALSE) -> Id4 | B5: =VLOOKUP(A5,'Customer Names'!A:E,4,FALSE) -> Kelsey | C5: =VLOOKUP(A5,'Medical Examinations'!A:J,2,FALSE) -> 38.095 | D5: =VLOOKUP(A5,'Medical Examinations'!A:J,3,FALSE) -> 6.05 | E5: =VLOOKUP(A5,'Medical Examinations'!A:J,4,FALSE) -> NO | F5: =VLOOKUP(A5,'Medical Examinations'!A:J,5,FALSE) -> No | G5: =VLOOKUP(A5,'Medical Examinations'!A:J,6,FALSE) -> No | H5: =VLOOKUP(A5,'Medical Examinations'!A:J,7,FALSE) -> 0 | I5: =VLOOKUP(A5,'Medical Examinations'!A:J,8,FALSE) -> YES | J5: =VLOOKUP(A5,'Medical Examinations'!A:J,9,FALSE) -> obesity | K5: =VLOOKUP(A5,'Medical Examinations'!A:J,10,FALSE) -> prediabetes | L5: =VLOOKUP(Healthcare!A5,'Hospitalisation Details'!A:K,10,FALSE) -> 6-Jun-1991 | M5: =VLOOKUP(A5,'Hospitalisation Details'!A:K,6,FALSE) -> 58571.07 | N5: =VLOOKUP(A5,'Hospitalisation Details'!A:K,7,FALSE) -> tier - 1 | O5: =VLOOKUP(A5,'Hospitalisation Details'!A:K,8,FALSE) -> tier - 3 | P5: =VLOOKUP(A5,'Hospitalisation Details'!A:K,9,FALSE) -> R1024 | Q5: =VLOOKUP(A5,'Hospitalisation Details'!A:K,11,FALSE) -> 32
A6: =VLOOKUP('Medical Examinations'!A6,'Medical Examinations'!A:A,1,FALSE) -> Id5 | B6: =VLOOKUP(A6,'Customer Names'!A:E,4,FALSE) -> Kristyn | C6: =VLOOKUP(A6,'Medical Examinations'!A:J,2,FALSE) -> 35.53 | D6: =VLOOKUP(A6,'Medical Examinations'!A:J,3,FALSE) -> 5.45 | E6: =VLOOKUP(A6,'Medical Examinations'!A:J,4,FALSE) -> NO | F6: =VLOOKUP(A6,'Medical Examinations'!A:J,5,FALSE) -> No | G6: =VLOOKUP(A6,'Medical Examinations'!A:J,6,FALSE) -> No | H6: =VLOOKUP(A6,'Medical Examinations'!A:J,7,FALSE) -> 0 | I6: =VLOOKUP(A6,'Medical Examinations'!A:J,8,FALSE) -> YES | J6: =VLOOKUP(A6,'Medical Examinations'!A:J,9,FALSE) -> obesity | K6: =VLOOKUP(A6,'Medical Examinations'!A:J,10,FALSE) -> normal | L6: =VLOOKUP(Healthcare!A6,'Hospitalisation Details'!A:K,10,FALSE) -> 19-Jun-1989 | M6: =VLOOKUP(A6,'Hospitalisation Details'!A:K,6,FALSE) -> 55135.4 | N6: =VLOOKUP(A6,'Hospitalisation Details'!A:K,7,FALSE) -> tier - 1 | O6: =VLOOKUP(A6,'Hospitalisation Details'!A:K,8,FALSE) -> tier - 2 | P6: =VLOOKUP(A6,'Hospitalisation Details'!A:K,9,FALSE) -> R1012 | Q6: =VLOOKUP(A6,'Hospitalisation Details'!A:K,11,FALSE) -> 34
A7: =VLOOKUP('Medical Examinations'!A7,'Medical Examinations'!A:A,1,FALSE) -> Id6 | B7: =VLOOKUP(A7,'Customer Names'!A:E,4,FALSE) -> Russell B. | C7: =VLOOKUP(A7,'Medical Examinations'!A:J,2,FALSE) -> 32.8 | D7: =VLOOKUP(A7,'Medical Examinations'!A:J,3,FALSE) -> 6.59 | E7: =VLOOKUP(A7,'Medical Examinations'!A:J,4,FALSE) -> NO | F7: =VLOOKUP(A7,'Medical Examinations'!A:J,5,FALSE) -> No | G7: =VLOOKUP(A7,'Medical Examinations'!A:J,6,FALSE) -> No | H7: =VLOOKUP(A7,'Medical Examinations'!A:J,7,FALSE) -> 0 | I7: =VLOOKUP(A7,'Medical Examinations'!A:J,8,FALSE) -> YES | J7: =VLOOKUP(A7,'Medical Examinations'!A:J,9,FALSE) -> obesity | K7: =VLOOKUP(A7,'Medical Examinations'!A:J,10,FALSE) -> diabetes | L7: =VLOOKUP(Healthcare!A7,'Hospitalisation Details'!A:K,10,FALSE) -> 4-Aug-1962 | M7: =VLOOKUP(A7,'Hospitalisation Details'!A:K,6,FALSE) -> 52590.83 | N7: =VLOOKUP(A7,'Hospitalisation Details'!A:K,7,FALSE) -> tier - 1 | O7: =VLOOKUP(A7,'Hospitalisation Details'!A:K,8,FALSE) -> tier - 3 | P7: =VLOOKUP(A7,'Hospitalisation Details'!A:K,9,FALSE) -> R1011 | Q7: =VLOOKUP(A7,'Hospitalisation Details'!A:K,11,FALSE) -> 61
A8: =VLOOKUP('Medical Examinations'!A8,'Medical Examinations'!A:A,1,FALSE) -> Id7 | B8: =VLOOKUP(A8,'Customer Names'!A:E,4,FALSE) -> Scott | C8: =VLOOKUP(A8,'Medical Examinations'!A:J,2,FALSE) -> 36.4 | D8: =VLOOKUP(A8,'Medical Examinations'!A:J,3,FALSE) -> 6.07 | E8: =VLOOKUP(A8,'Medical Examinations'!A:J,4,FALSE) -> NO | F8: =VLOOKUP(A8,'Medical Examinations'!A:J,5,FALSE) -> No | G8: =VLOOKUP(A8,'Medical Examinations'!A:J,6,FALSE) -> No | H8: =VLOOKUP(A8,'Medical Examinations'!A:J,7,FALSE) -> 0 | I8: =VLOOKUP(A8,'Medical Examinations'!A:J,8,FALSE) -> YES | J8: =VLOOKUP(A8,'Medical Examinations'!A:J,9,FALSE) -> obesity | K8: =VLOOKUP(A8,'Medical Examinations'!A:J,10,FALSE) -> prediabetes | L8: =VLOOKUP(Healthcare!A8,'Hospitalisation Details'!A:K,10,FALSE) -> 27-Oct-1994 | M8: =VLOOKUP(A8,'Hospitalisation Details'!A:K,6,FALSE) -> 51194.56 | N8: =VLOOKUP(A8,'Hospitalisation Details'!A:K,7,FALSE) -> tier - 1 | O8: =VLOOKUP(A8,'Hospitalisation Details'!A:K,8,FALSE) -> tier - 3 | P8: =VLOOKUP(A8,'Hospitalisation Details'!A:K,9,FALSE) -> R1011 | Q8: =VLOOKUP(A8,'Hospitalisation Details'!A:K,11,FALSE) -> 29
A9: =VLOOKUP('Medical Examinations'!A9,'Medical Examinations'!A:A,1,FALSE) -> Id8 | B9: =VLOOKUP(A9,'Customer Names'!A:E,4,FALSE) -> Stephen | C9: =VLOOKUP(A9,'Medical Examinations'!A:J,2,FALSE) -> 36.96 | D9: =VLOOKUP(A9,'Medical Examinations'!A:J,3,FALSE) -> 7.93 | E9: =VLOOKUP(A9,'Medical Examinations'!A:J,4,FALSE) -> NO | F9: =VLOOKUP(A9,'Medical Examinations'!A:J,5,FALSE) -> No | G9: =VLOOKUP(A9,'Medical Examinations'!A:J,6,FALSE) -> No | H9: =VLOOKUP(A9,'Medical Examinations'!A:J,7,FALSE) -> 3 | I9: =VLOOKUP(A9,'Medical Examinations'!A:J,8,FALSE) -> YES | J9: =VLOOKUP(A9,'Medical Examinations'!A:J,9,FALSE) -> obesity | K9: =VLOOKUP(A9,'Medical Examinations'!A:J,10,FALSE) -> diabetes | L9: =VLOOKUP(Healthcare!A9,'Hospitalisation Details'!A:K,10,FALSE) -> 27-Jun-1958 | M9: =VLOOKUP(A9,'Hospitalisation Details'!A:K,6,FALSE) -> 49577.66 | N9: =VLOOKUP(A9,'Hospitalisation Details'!A:K,7,FALSE) -> tier - 2 | O9: =VLOOKUP(A9,'Hospitalisation Details'!A:K,8,FALSE) -> tier - 2 | P9: =VLOOKUP(A9,'Hospitalisation Details'!A:K,9,FALSE) -> R1013 | Q9: =VLOOKUP(A9,'Hospitalisation Details'!A:K,11,FALSE) -> 65
A10: =VLOOKUP('Medical Examinations'!A10,'Medical Examinations'!A:A,1,FALSE) -> Id9 | B10: =VLOOKUP(A10,'Customer Names'!A:E,4,FALSE) -> Patrick R. | C10: =VLOOKUP(A10,'Medical Examinations'!A:J,2,FALSE) -> 41.14 | D10: =VLOOKUP(A10,'Medical Examinations'!A:J,3,FALSE) -> 9.58 | E10: =VLOOKUP(A10,'Medical Examinations'!A:J,4,FALSE) -> YES | F10: =VLOOKUP(A10,'Medical Examinations'!A:J,5,FALSE) -> No | G10: =VLOOKUP(A10,'Medical Examinations'!A:J,6,FALSE) -> Yes | H10: =VLOOKUP(A10,'Medical Examinations'!A:J,7,FALSE) -> 1 | I10: =VLOOKUP(A10,'Medical Examinations'!A:J,8,FALSE) -> YES | J10: =VLOOKUP(A10,'Medical Examinations'!A:J,9,FALSE) -> obesity | K10: =VLOOKUP(A10,'Medical Examinations'!A:J,10,FALSE) -> diabetes | L10: =VLOOKUP(Healthcare!A10,'Hospitalisation Details'!A:K,10,FALSE) -> 4-Sep-1963 | M10: =VLOOKUP(A10,'Hospitalisation Details'!A:K,6,FALSE) -> 48970.25 | N10: =VLOOKUP(A10,'Hospitalisation Details'!A:K,7,FALSE) -> tier - 1 | O10: =VLOOKUP(A10,'Hospitalisation Details'!A:K,8,FALSE) -> tier - 2 | P10: =VLOOKUP(A10,'Hospitalisation Details'!A:K,9,FALSE) -> R1013 | Q10: =VLOOKUP(A10,'Hospitalisation Details'!A:K,11,FALSE) -> 60
A11: =VLOOKUP('Medical Examinations'!A11,'Medical Examinations'!A:A,1,FALSE) -> Id10 | B11: =VLOOKUP(A11,'Customer Names'!A:E,4,FALSE) -> Brooke N. | C11: =VLOOKUP(A11,'Medical Examinations'!A:J,2,FALSE) -> 38.06 | D11: =VLOOKUP(A11,'Medical Examinations'!A:J,3,FALSE) -> 10.79 | E11: =VLOOKUP(A11,'Medical Examinations'!A:J,4,FALSE) -> NO | F11: =VLOOKUP(A11,'Medical Examinations'!A:J,5,FALSE) -> No | G11: =VLOOKUP(A11,'Medical Examinations'!A:J,6,FALSE) -> No | H11: =VLOOKUP(A11,'Medical Examinations'!A:J,7,FALSE) -> 0 | I11: =VLOOKUP(A11,'Medical Examinations'!A:J,8,FALSE) -> YES | J11: =VLOOKUP(A11,'Medical Examinations'!A:J,9,FALSE) -> obesity | K11: =VLOOKUP(A11,'Medical Examinations'!A:J,10,FALSE) -> diabetes | L11: =VLOOKUP(Healthcare!A11,'Hospitalisation Details'!A:K,10,FALSE) -> 29-Dec-1978 | M11: =VLOOKUP(A11,'Hospitalisation Details'!A:K,6,FALSE) -> 48885.14 | N11: =VLOOKUP(A11,'Hospitalisation Details'!A:K,7,FALSE) -> tier - 1 | O11: =VLOOKUP(A11,'Hospitalisation Details'!A:K,8,FALSE) -> tier - 2 | P11: =VLOOKUP(A11,'Hospitalisation Details'!A:K,9,FALSE) -> R1013 | Q11: =VLOOKUP(A11,'Hospitalisation Details'!A:K,11,FALSE) -> 45
A12: =VLOOKUP('Medical Examinations'!A12,'Medical Examinations'!A:A,1,FALSE) -> Id11 | B12: =VLOOKUP(A12,'Customer Names'!A:E,4,FALSE) -> Paola Andrea | C12: =VLOOKUP(A12,'Medical Examinations'!A:J,2,FALSE) -> 37.7 | D12: =VLOOKUP(A12,'Medical Examinations'!A:J,3,FALSE) -> 5.96 | E12: =VLOOKUP(A12,'Medical Examinations'!A:J,4,FALSE) -> YES | F12: =VLOOKUP(A12,'Medical Examinations'!A:J,5,FALSE) -> No | G12: =VLOOKUP(A12,'Medical Examinations'!A:J,6,FALSE) -> No | H12: =VLOOKUP(A12,'Medical Examinations'!A:J,7,FALSE) -> 2 | I12: =VLOOKUP(A12,'Medical Examinations'!A:J,8,FALSE) -> YES | J12: =VLOOKUP(A12,'Medical Examinations'!A:J,9,FALSE) -> obesity | K12: =VLOOKUP(A12,'Medical Examinations'!A:J,10,FALSE) -> prediabetes | L12: =VLOOKUP(Healthcare!A12,'Hospitalisation Details'!A:K,10,FALSE) -> 22-Jul-1959 | M12: =VLOOKUP(A12,'Hospitalisation Details'!A:K,6,FALSE) -> 48824.45 | N12: =VLOOKUP(A12,'Hospitalisation Details'!A:K,7,FALSE) -> tier - 2 | O12: =VLOOKUP(A12,'Hospitalisation Details'!A:K,8,FALSE) -> tier - 1 | P12: =VLOOKUP(A12,'Hospitalisation Details'!A:K,9,FALSE) -> R1011 | Q12: =VLOOKUP(A12,'Hospitalisation Details'!A:K,11,FALSE) -> 64
A13: =VLOOKUP('Medical Examinations'!A13,'Medical Examinations'!A:A,1,FALSE) -> Id12 | B13: =VLOOKUP(A13,'Customer Names'!A:E,4,FALSE) -> David | C13: =VLOOKUP(A13,'Medical Examinations'!A:J,2,FALSE) -> 42.13 | D13: =VLOOKUP(A13,'Medical Examinations'!A:J,3,FALSE) -> 11.9 | E13: =VLOOKUP(A13,'Medical Examinations'!A:J,4,FALSE) -> NO | F13: =VLOOKUP(A13,'Medical Examinations'!A:J,5,FALSE) -> No | G13: =VLOOKUP(A13,'Medical Examinations'!A:J,6,FALSE) -> No | H13: =VLOOKUP(A13,'Medical Examinations'!A:J,7,FALSE) -> 0 | I13: =VLOOKUP(A13,'Medical Examinations'!A:J,8,FALSE) -> YES | J13: =VLOOKUP(A13,'Medical Examinations'!A:J,9,FALSE) -> obesity | K13: =VLOOKUP(A13,'Medical Examinations'!A:J,10,FALSE) -> diabetes | L13: =VLOOKUP(Healthcare!A13,'Hospitalisation Details'!A:K,10,FALSE) -> 27-Oct-1965 | M13: =VLOOKUP(A13,'Hospitalisation Details'!A:K,6,FALSE) -> 48675.52 | N13: =VLOOKUP(A13,'Hospitalisation Details'!A:K,7,FALSE) -> tier - 1 | O13: =VLOOKUP(A13,'Hospitalisation Details'!A:K,8,FALSE) -> tier - 2 | P13: =VLOOKUP(A13,'Hospitalisation Details'!A:K,9,FALSE) -> R1013 | Q13: =VLOOKUP(A13,'Hospitalisation Details'!A:K,11,FALSE) -> 58
... A2336: =VLOOKUP('Medical Examinations'!A2336,'Medical Examinations'!A:A,1,FALSE) -> Id2335 | B2336: =VLOOKUP(A2336,'Customer Names'!A:E,4,FALSE) -> Aaron K | C2336: =VLOOKUP(A2336,'Medical Examinations'!A:J,2,FALSE) -> 17.58 | D2336: =VLOOKUP(A2336,'Medical Examinations'!A:J,3,FALSE) -> 4.51 | E2336: =VLOOKUP(A2336,'Medical Examinations'!A:J,4,FALSE) -> NO | F2336: =VLOOKUP(A2336,'Medical Examinations'!A:J,5,FALSE) -> No | G2336: =VLOOKUP(A2336,'Medical Examinations'!A:J,6,FALSE) -> No | H2336: =VLOOKUP(A2336,'Medical Examinations'!A:J,7,FALSE) -> 1 | I2336: =VLOOKUP(A2336,'Medical Examinations'!A:J,8,FALSE) -> YES | J2336: =VLOOKUP(A2336,'Medical Examinations'!A:J,9,FALSE) -> underweight | K2336: =VLOOKUP(A2336,'Medical Examinations'!A:J,10,FALSE) -> normal | L2336: =VLOOKUP(Healthcare!A2336,'Hospitalisation Details'!A:K,10,FALSE) -> 9-Jul-1992 | M2336: =VLOOKUP(A2336,'Hospitalisation Details'!A:K,6,FALSE) -> 563.84 | N2336: =VLOOKUP(A2336,'Hospitalisation Details'!A:K,7,FALSE) -> tier - 2 | O2336: =VLOOKUP(A2336,'Hospitalisation Details'!A:K,8,FALSE) -> tier - 3 | P2336: =VLOOKUP(A2336,'Hospitalisation Details'!A:K,9,FALSE) -> R1013 | Q2336: =VLOOKUP(A2336,'Hospitalisation Details'!A:K,11,FALSE) -> 31

Sheet pivot
A1: Count of Customer ID | B1: Column Labels | H1: Any Transplants | I1: Average of HBA1C | J1: Sum of Number of major surgeries
A2: Smoker | B2: No | C2: Yes | D2: Grand Total | H2: No | I2: 6.7888889 | J2: 104
A3: NO | B3: 127 | C3: 28 | D3: 155 | H3: yes | I3: 4.866 | J3: 5
A4: YES | B4: 19 | C4: 2 | D4: 21 | H4: Grand Total | I4: 6.7342614 | J4: 109
A5: Grand Total | B5: 146 | C5: 30 | D5: 176
A23: Average of Charges | B23: Column Labels | H23: Average of Charges | I23: Column Labels
A24: Weight | B24: diabetes | C24: normal | D24: prediabetes | E24: Grand Total | H24: State ID | I24: tier - 1 | J24: tier - 2 | K24: tier - 3 | L24: Grand Total
A25: underweight | B25: 7442.9649 | C25: 6911.0056 | D25: 5647.7483 | E25: 6899.3175 | H25: R1011 | I25: 27524.693 | J25: 19802.179 | K25: 8322.47 | L25: 20655.156
A26: Grand Total | B26: 7442.9649 | C26: 6911.0056 | D26: 5647.7483 | E26: 6899.3175 | H26: R1012 | I26: 29227.6 | J26: 5443.5931 | K26: 6337.122 | L26: 6097.979
H27: R1013 | J27: 3705.8558 | K27: 3725.9904 | L27: 3711.4848
H28: R1015 | J28: 1694.8 | L28: 1694.8
H29: R1016 | K29: 12829.46 | L29: 12829.46
H30: R1017 | K30: 11534.87 | L30: 11534.87
H31: R1019 | J31: 6640.54 | L31: 6640.54
H32: R1024 | J32: 8648.058 | K32: 13204.29 | L32: 9407.43
H33: Grand Total | I33: 27737.556 | J33: 6107.9082 | K33: 5304.3571 | L33: 6899.3175
A47: Age | B47: Average of BMI | C47: Average of HBA1C | H47: Age | I47: Avg og BMI
A48: 19 | B48: 16.79 | C48: 4.86 | H48: 19 | I48: 31.205663
A49: 20 | B49: 17.13 | C49: 4.7675 | H49: 20 | I49: 29.523412
A50: 21 | B50: 16.9275 | C50: 9.66625 | H50: 21 | I50: 28.111818
A51: 22 | B51: 16.685 | C51: 4.586 | H51: 22 | I51: 29.992653
A52: 23 | B52: 17.035 | C52: 4.875 | H52: 23 | I52: 32.2475
A53: 24 | B53: 16.275 | C53: 4.8733333 | H53: 24 | I53: 30.86598
A54: 25 | B54: 16.8 | C54: 5.4025 | H54: 25 | I54: 28.927979
A55: 26 | B55: 16.461429 | C55: 5.0557143 | H55: 26 | I55: 30.402
A56: 27 | B56: 16.999 | C56: 5.254 | H56: 27 | I56: 30.441364
A57: 28 | B57: 16.613 | C57: 5.096 | H57: 28 | I57: 30.038302
A58: 29 | B58: 16.715 | C58: 4.92 | H58: 29 | I58: 31.258909
A59: 30 | B59: 16.976 | C59: 5.626 | H59: 30 | I59: 30.566509
... A88: 61 | B88: 17.23875 | C88: 10.5 | H88: 59 | I88: 32.739667
A89: Grand Total | B89: 16.898324 | C89: 6.7342614 | H89: 60 | I89: 31.474792
H90: 61 | I90: 31.6071
H91: 62 | I91: 32.548261
H92: 63 | I92: 32.342609
H93: 64 | I93: 31.923478
H94: 65 | I94: 32.976136
H95: Grand Total | I95: 30.972649
A98: Age | B98: Average of HBA1C | D98: Age | E98: Avg of HBA1C
A99: 19 | B99: 4.86 | D99: 19 | E99: 5.1439796
A100: 20 | B100: 4.7675 | D100: 20 | E100: 5.1927059
...

Sheet Dashboard
B1: HEALTH CARE ANALYSIS DASHBOARD
Z2: Count of Customer ID
Z3: 176
Z4: Average of Charges
Z5: 6899.3175
Z6: Average of BMI
Z7: 16.898324
Z8: Average of HBA1C
Z9: 6.7342614
Z10: Sum of Number of major surgeries
Z11: 109
